Workbook

Sheet Staff Inventory
A1: S/N | B1: Staff Name | C1: Department | D1: Position | E1: Employment Date | F1: Email | G1: Phone Number | H1: Registered Under | I1: Branch
A2: 1 | B2: IZUNYON BLESSING | C2: APPLICATION | D2: STUDENT COUNSELLOR | E2: 16th FEBRUARY 2026 | F2: izunyon.basechaninternational@gmail.com | G2: 8136865810 | I2: Benin Branch
A3: 2 | B3: Peter Abah | C3: Conversion | D3: Conversion | E3: 44621 | F3: peter.basechaninternational@gmail.com | G3: 8093992308 | I3: Abuja Branch
A4: 3 | B4: Cletus Anioke | C4: Marketing and Sales | D4: Team Lead | E4: 44515 | F4: cletus.basechaninternational@gmail.com | G4: 9037405864 | H4: Personal | I4: Abuja Branch
A5: 4 | B5: Egbase Johnmary | C5: IT DEPARTMENT | D5: IT EXEC | E5: FEBUARY 2026 | F5: Johnmary.basechaninternational@gmail.com | G5: 8126014579 | H5: Personal BVN | I5: Abuja Branch
A6: 5 | B6: JUMAI ADAMU | C6: Application | D6: Team Lead | E6: 44661 | F6: jumaibasechaninternational@gmail.com | G6: 9030157384 | H6: Basechan | I6: Abuja Branch
A7: 6 | B7: Nwaiwu Blessing (Oge) | C7: Marketing/applications | D7: Student Counsellor | E7: 2nd March, 2026 | F7: nwaiwu.basechaninternational@gmail.com | G7: =+234 813 467 0164 -> #ERROR! | H7: Basechan International Limited | I7: Benin Branch
A8: 7 | B8: Feridu Yakubu | C8: Conversion | D8: Branch Supervisor | E8: 3rd January 2023 | F8: feridu.basechaninternational@gmail.com | G8: 8063832238 | H8: Personal BVN | I8: Benin Branch
A9: 8 | B9: Effiong Oyonumo | C9: Applications | D9: Counsellor | E9: 44962 | F9: effiong.basechaninternational@gmail.com | G9: 8168356245 | H9: Personal BVN | I9: Abuja Branch
A10: 9 | B10: Imuekemhe Oshioke | C10: Management | D10: Manager | E10: 45293 | F10: Collins@basechaninternational.com | G10: 8100517652 | H10: MTN | I10: Abuja Branch

Sheet  Physical Assets
A1: S/N | B1: Asset Tag ID | C1: Category (Laptop/Monitor/Mobile) | D1: Make & Model | E1: Serial Number | F1: Assigned Staff | G1: Department | H1: Physical Location | I1: Purchase Date | J1: Condition | K1: Status (Active/Repair/Retired)
A2: 1 | C2: Laptop | D2: HP Elitebook 840 G6 | E2: 5CG9439J8N | F2: BLESSING | G2: APPLICATION | H2: Benin Branch | I2: 27th Jan. 2026 | J2: fairly used in good condition | K2: Active
A3: 2 | C3: Monitor | D3: HP ProOne 400 G2 20-in Non-Touch AiO | E3: 0813089A-E092-4710-8A73-77B980C31449 | F3: Peter Abah | G3: Conversion | H3: Abuja Branch | J3: Good | K3: Active
A4: 3 | C4: Desktop computer | D4: DESKTOP LG8N6S8 | F4: Cletus Anioke | G4: Marketing and sales | H4: Abuja Branch | J4: Lags, freezes, and malfunctions frequently | K4: functional
A5: 4 | C5: Keyboard | F5: Cletus Anioke | G5: Marketing and sales | H5: Abuja Branch | J5: In good condition | K5: functional
A6: 5 | C6: Mouse | F6: Cletus Anioke | G6: Marketing and sales | H6: Abuja Branch | J6: In good condition | K6: functional
A7: 6 | C7: Desk | F7: Cletus Anioke | G7: Marketing and sales | H7: Abuja Branch | J7: In good condition | K7: functional
A8: 7 | C8: Drawer | F8: Cletus Anioke | G8: Marketing and sales | H8: Abuja Branch | J8: In good condition | K8: functional
A9: 8 | C9: SIM card | F9: Cletus Anioke | G9: Marketing and sales | H9: Abuja Branch | J9: In good condition | K9: functional
A10: 9 | C10: LAPTOP | D10: HP 840 G | F10: EGBASE JOHNMARY | G10: IT & Infrastructure Systems | H10: Abuja Branch | I10: 46138 | J10: fairly used in good condition | K10: ACTIVE
A11: 10 | C11: Desktop | D11: HP | E11: DESKTOP-RODQ0JJ | F11: JUMAI | G11: APPLICATION | H11: Abuja Branch | J11: GOOD | K11: ACTIVE
A12: 11 | C12: Keyboard | D12: HP | F12: JUMAI | G12: APPLICATION | H12: Abuja Branch | J12: GOOD | K12: ACTIVE
A13: 12 | C13: Mouse | F13: JUMAI | G13: APPLICATION | H13: Abuja Branch | J13: GOOD | K13: ACTIVE
A14: 13 | C14: Laptop | D14: HP EliteBook 840 G6 | E14: 5CG0091F0M | F14: Nwaiwu Blessing (Oge) | G14: Marketing/applications | H14: Benin Branch | I14: 27th January, 2026 | J14: Fairly used and in good condition | K14: ACTIVE
A15: 14 | C15: HP laptop Core i7 | D15: HP EliteBook 840 G6 | E15: 5CG9503PS8 | F15: Feridu | G15: Conversion | H15: Benin Branch | I15: 27/01/2026s
A16: 15 | C16: Monitor, | D16: HP | F16: Effiong Oyonumo | G16: Applications | H16: Abuja Branch | J16: fairly used in good condition | K16: Active
A17: 16 | C17: Headset | F17: Effiong Oyonumo | G17: Applications | H17: Abuja Branch | J17: fairly used and in bad condition | K17: Retired
A18: 17 | C18: Mouse | F18: Effiong Oyonumo | G18: Applications | H18: Abuja Branch | J18: fairly used in good condition | K18: Active
A19: 18 | C19: Keyboard | F19: Effiong Oyonumo | G19: Applications | H19: Abuja Branch | J19: fairly used in good condition | K19: Active
A20: 19 | C20: Laptop | D20: HP | E20: SN5CG0281MHC | F20: Effiong Oyonumo | G20: Applications | H20: Abuja Branch | J20: new and in good condition | K20: Active
A21: 20 | C21: Hp Desktop | D21: HP ProOne 400 G2 20 | E21: T962NFQ | F21: IMUEKEMHE COLLINS | G21: MANAGEMENT | H21: Abuja Branch | J21: USED | K21: ACTIVE
A22: 21 | C22: HP Laptop | D22: HP EliteBook 940 G6 | J22: USED | K22: ACTIVE
A23: 22 | C23: Acer Laptop | D23: Acer Chrome book Plus | E23: NXKNUEK00645003CDD3400 | J23: USED | K23: ACTIVE

Sheet  Digital&Accounts
A1: S/N | B1: Platform / Software | C1: Account / Login Email | D1: Sub-Agent / Handle ID | E1: Assigned User | F1: User Role | G1: Passwords | H1: Password Vault Status
A2: 1 | B2: Microsoft office suite | E2: Blessing | F2: user
A3: 2 | B3: Firmli CRM | C3: izunyon.basechaninternational@gmail.com | E3: Blessing | F3: user | G3: Basechan@2026
A4: 3 | B4: Google workspace | C4: izunyon.basechaninternational@gmail.com | E4: Blessing | F4: user | G4: Basechan@2026
A5: 4 | B5: crizac | C5: izunyon.basechaninternational@gmail.com | E5: Blessing | F5: user | G5: Basechan@2026
A6: 5 | B6: siuk | C6: izunyon.basechaninternational@gmail.com | E6: Blessing | F6: user | G6: Basechan@2026
A7: 6 | B7: EDVOY | C7: izunyon.basechaninternational@gmail.com | E7: Blessing | F7: user | G7: Basechan@2026
A8: 7 | B8: Basechan | C8: peter.basechaninternational@gmail.com | E8: Peter Abah | F8: B2B Account Manager & Counsellor | G8: password
A9: 8 | B9: Crizac | C9: peter.basechaninternational@gmail.com | E9: Peter Abah | F9: Staff Account & Counsellor | G9: Basechan2022@
A10: 9 | B10: SIUK | C10: peter.basechaninternational@gmail.com | E10: Peter Abah | F10: Staff Account & Counsellor | G10: Basechan2022@
A11: 10 | B11: Edvoy | C11: peter@basechancontractors.co.uk | E11: Cletus Anioke | F11: Staff Account & Counsellor | G11: Basechan2022@
A12: 11 | B12: basechan-team.web.app | C12: cletus.basechaninternational@gmail.com | D12: Babs | E12: Cletus Anioke | F12: User | G12: Cletus@2023 | H12: Google password manager
A13: 12 | B13: https://basechan-team.web.app/ | D13: Ayomide travel | E13: Cletus Anioke | F13: User | H13: Google password manager
A14: 13 | D14: Marvel home | E14: Cletus Anioke | F14: User | H14: Google password manager
A15: 14 | B15: canva.com | D15: Bonaventure | E15: Cletus Anioke | F15: User | G15: Nigeria2023* | H15: Google password manager
A16: 15 | B16: https://www.canva.com/ | E16: Cletus Anioke | F16: User | H16: Google password manager
A17: 16 | B17: crizac.com | E17: Cletus Anioke | F17: User | H17: Google password manager
A18: 17 | B18: https://www.crizac.com/authentication/login | C18: cletus.basechaninternational@gmail.com | E18: Cletus Anioke | F18: User | G18: Cletus@2023 | H18: Google password manager
A19: 18 | B19: lsbu.ac.uk | E19: Cletus Anioke | F19: User | H19: Google password manager
A20: 19 | B20: https://apply-international.lsbu.ac.uk/signin | C20: applications@basechaninternational.com | E20: Cletus Anioke | F20: User | G20: Basechan*2026 | H20: Google password manager
A21: 20 | B21: Gmail google.com | C21: cletus.basechaninternational@gmail.com | E21: Cletus Anioke | F21: User | G21: Cletus@2023 | H21: Google password manager
A22: 21 | B22: si-applications.com | E22: Cletus Anioke | F22: User | H22: Google password manager
A23: 22 | B23: https://www.si-applications.com/auth/login | C23: cletus.basechaninternational@gmail.com | E23: Cletus Anioke | F23: User | G23: RyRVsn6Tr4 | H23: Google password manager
A24: 23 | B24: Basechan CRM | C24: cletus.basechaninternational@gmail.com | E24: Cletus Anioke | F24: User | G24: password | H24: Google password manager
A25: 24 | B25: CANVA | C25: Basechan international@gmail.con | E25: EGBASE JOHNMARY | F25: USER | G25: Nigeria2023*
A26: 25 | B26: FIRMLY CRM | C26: ithub@basechaninternational.com | E26: EGBASE JOHNMARY | F26: TECH SUPPORT/ADMIN | G26: Tech@123!
A27: 26 | B27: GOOGLE WORKSPACE | C27: ithub@basechaninternational.com | E27: EGBASE JOHNMARY | F27: TECH SUPPORT | G27: Basechan@2026
A28: 27 | B28: Microsoft office suite | C28: nwaiwu.basechaninternational@gmail.com | E28: Nwaiwu Blessing (Oge) | F28: User | G28: Basechan*2026
A29: 28 | B29: Firmli CRM | C29: nwaiwu.basechaninternational@gmail.com | E29: Nwaiwu Blessing (Oge) | F29: User | G29: Basechan*2026
A30: 29 | B30: Google workspace | C30: nwaiwu.basechaninternational@gmail.com | E30: Nwaiwu Blessing (Oge) | F30: User | G30: Basechan*2026
A31: 30 | B31: Crizac | C31: nwaiwu.basechaninternational@gmail.com | E31: Nwaiwu Blessing (Oge) | F31: User | G31: Basechan*2026
A32: 31 | B32: Si UK | C32: nwaiwu.basechaninternational@gmail.com | E32: Nwaiwu Blessing (Oge) | F32: User | G32: Basechan*2026
A33: 32 | B33: CRIZAC | C33: feridu.basechaninternstional@gmail.com/Feridu@2023 | E33: Feridu | G33: Feridu@2023
A34: 33 | B34: SIUK | C34: feridu.basechaninternstional@gmail.com | E34: Feridu | G34: Feridu@2023
A35: 34 | B35: UAP | C35: info@basechaninternational.com | E35: Feridu | G35: Basechan@2026
A36: 35 | B36: CEG | C36: EMP34601.1 | E36: Feridu | G36: International@15*
A37: 36 | B37: Sunderland | C37: N7.5 | E37: Feridu | G37: Feridu@2023
A38: 37 | D38: Ellamendez | E38: Feridu | G38: no access to login
A39: 38 | D39: Oasis Computer | E39: Feridu | G39: no access to login
A40: 39 | D40: Aishat(sub-agent) | E40: Feridu
...

Sheet Data&Workbooks
A1: S/N | B1: Workbook / Doc Title | C1: Business Function | D1: Cloud Storage Link (URL) | E1: Primary File Owner | F1: Department | G1: Access Permissions | H1: Last Audit Date
A2: 1 | B2: Basechan Benin Branch Lead Spreadsheet | D2: https://docs.google.com/spreadsheets/d/10g2DN4Yf9pxSKFgZbGuTVzO6uYzS_B42gKejl0Yv5tI/edit?ouid=113810905748685353074&usp=sheets_home&ths=true | E2: Basechan | F2: Application/Report | G2: ALL | H2: 24th Sept. 2026
A3: 2 | B3: Team Lead Spreadsheet | D3: https://docs.google.com/spreadsheets/d/12YF7NGuEJrIQA02ERmPzxLlTbdzwJYR1wvAWlQLu82I/edit | E3: Basechan | F3: Lead management/Marketing | H3: 18th Sept. 2026
A4: 3 | B4: Crizac Spreadsheet | D4: https://docs.google.com/spreadsheets/d/1E5MU8BmMhotD5ty6IeZ7dyw0XuYsiHrU8SG65Nbu3DU/edit | E4: Basechan | F4: Application | H4: 18th Sept. 2026
A5: 4 | B5: ALL DEPOSITS | C5: Deposit Report | D5: https://docs.google.com/spreadsheets/d/1JnDAR148sOcjcjByYyb88hOLIZnyPpIluV6YvtFNUEs/edit?gid=107644410#gid=107644410 | E5: peter.basechaninternational@gmail.com | F5: Conversion | G5: collinsbasechan@gmail.com, egbase@basechaninternational.com, feridu.basechaninternational@gmail.com, info@basechaninternational.com, ithub@basechaninternational.com, johnmary.basechaninternational@gmail.com, jumaibasechaninternational@gmail.com, suhas.chandran22@gmail.com
A6: 5 | B6: TEAM - LEADS SPREADSHEET - Google Sheets
A7: 6 | B7: Marketing Status Report - Google Sheets
A8: 7 | B8: Basechan International Admissions Application (Responses) - Google Sheets
A9: 8 | B9: https://docs.google.com/spreadsheets/d/1E5MU8BmMhotD5ty6IeZ7dyw0XuYsiHrU8SG65Nbu3DU/edit?gid=1642543170#gid=1642543170
A10: 9 | B10: Google | C10: jumaibasechaninternational@gmail.com | E10: JUMAI | F10: User | G10: Jumai@2022 | H10: Google Manager
A11: 10 | B11: Basechan CRM | C11: jumaibasechaninternational@gmail.com | E11: JUMAI | F11: Counselor | G11: Jumai@2022 | H11: Google Manager
A12: 11 | B12: SI-UK CRM | C12: jumaibasechaninternational@gmail.com | E12: JUMAI | F12: User | G12: Jumai@2022 | H12: Google Manager
A13: 12 | B13: CRIZAC | C13: jumaibasechaninternational@gmail.com | E13: JUMAI | F13: User | G13: Jumai@2022 | H13: Google Manager
A14: 13 | B14: Basechan Benin Branch Lead Spreadsheet | D14: https://docs.google.com/spreadsheets/d/10g2DN4Yf9pxSKFgZbGuTVzO6uYzS_B42gKejl0Yv5tI/edit?ouid=113810905748685353074&usp=sheets_home&ths=true | E14: Basechan | F14: Application/Report | G14: ALL | H14: 22nd Sept. 2026
A15: 14 | B15: Team Lead Spreadsheet | D15: https://docs.google.com/spreadsheets/d/12YF7NGuEJrIQA02ERmPzxLlTbdzwJYR1wvAWlQLu82I/edit | E15: Basechan | F15: Lead management/Marketing | H15: 10th Sept. 2026
A16: 15 | B16: Crizac Spreadsheet | D16: https://docs.google.com/spreadsheets/d/1E5MU8BmMhotD5ty6IeZ7dyw0XuYsiHrU8SG65Nbu3DU/edit | E16: Basechan | F16: Application | H16: 23rd Sept. 2026
A17: 16 | B17: Benin BranchSpreadsheet | D17: https://docs.google.com/spreadsheets/d/10g2DN4Yf9pxSKFgZbGuTVzO6uYzS_B42gKejl0Yv5tI/edit?ouid=113810905748685353074&usp=sheets_home&ths=true | E17: Basechan | F17: ALL | H17: 46283
A18: 17 | B18: Team Lead Spreadsheet | D18: https://docs.google.com/spreadsheets/d/12YF7NGuEJrIQA02ERmPzxLlTbdzwJYR1wvAWlQLu82I/edit | E18: Basechan | F18: Lead management/Marketing | H18: 46283
A19: 18 | B19: Deposit Spreadsheet | D19: https://docs.google.com/spreadsheets/d/1JnDAR148sOcjcjByYyb88hOLIZnyPpIluV6YvtFNUEs/edit | E19: Basechan | F19: Conversion | H19: 46287
A20: 19 | B20: Referral | D20: https://docs.google.com/spreadsheets/d/14zwDNI-gjhGAxLGPfpQDKpmD7uBu9MSvQ5GECSQ19dk/edit?gid=0#gid=0 | E20: Basechan | F20: ALL | G20: Management
A21: 20 | B21: 2026 Mid Year spreadshet | D21: https://docs.google.com/spreadsheets/d/1sANdkSAgNSirxkC2uAwcWlGiBrGtYV2ihUXM1rYgNi0/edit?gid=0#gid=0 | E21: Basechan | F21: ALL | G21: Application
A22: 21 | B22: Application Report Spreadsheet | D22: https://docs.google.com/spreadsheets/d/1-0IgKS0FieBtvj44hZoiGxFFfmLaXtr1k9GzCyzw9NY/edit?gid=1952566712#gid=1952566712 | E22: Basechan | F22: Application | G22: Application | H22: 46287
A23: 22 | B23: Team Leads | D23: https://docs.google.com/spreadsheets/d/12YF7NGuEJrIQA02ERmPzxLlTbdzwJYR1wvAWlQLu82I/edit
A24: 23 | B24: Agent Leads | D24: https://docs.google.com/spreadsheets/d/1wYyuc0NZ-iX9yjhVls7WAyTrRI8Hcs0ZHEJ8tqbez3c/edit?gid=240502715#gid=240502715
B25: APPLICATION REPORT | C25: APPLICATION | D25: https://docs.google.com/spreadsheets/d/1-0IgKS0FieBtvj44hZoiGxFFfmLaXtr1k9GzCyzw9NY/edit?gid=582638336#gid=582638336 | E25: basechannigeria@gmail.com | F25: Managemet | G25: owner | H25: 46291
C26: Deposit Chase | D26: https://docs.google.com/spreadsheets/d/133G1XFh-0ssJoZkk_LUlzarkIEOnozcmeEUMXVj0GeQ/edit?gid=0#gid=0 | E26: basechannigeria@gmail.com | F26: Managemet | G26: owner | H26: 46291

Sheet Office&Facilities
A1: S/N | B1: Infrastructure ID | C1: Item Description | D1: Category (Furniture/Network/Peripheral) | E1: Room / Zone | F1: Quantity | G1: Purchase Date | H1: Condition | I1: Assigned / Shared | J1: Maintenance Notes
A2: 1 | B2: ABUJA | C2: Chair | D2: FURNITURE | F2: 15
A3: 2 | B3: ABUJA | C3: Table | D3: FURNITURE | F3: 4
A4: 3 | B4: ABUJA | C4: Air conditions | D4: HARDWARE | F4: 4
A5: 4 | B5: ABUJA | C5: Fan | D5: HARDWARE | F5: 2
A6: 5 | B6: ABUJA | C6: Mouse | D6: HARDWARE | F6: 8
A7: 6 | B7: ABUJA | C7: Keyboard | D7: HARDWARE | F7: 9
A8: 7 | B8: ABUJA | C8: 4 user workspace | D8: FURNITURE | F8: 2
A9: 8 | B9: ABUJA | C9: Monitor | D9: HARDWARE | F9: 9
A10: 9 | B10: ABUJA | C10: Printer | D10: HARDWARE | F10: 1
A11: 10 | B11: ABUJA | C11: Router | D11: HARDWARE | F11: 2
A12: 11 | B12: ABUJA | C12: Storage unit | D12: FURNITURE | F12: 1
A13: 12 | B13: ABUJA | C13: Confy chair 2 | D13: FURNITURE | F13: 2
... A34: 33 | B34: BENIN | C34: three seat visitor chair | D34: FURNITURE | F34: 1
A35: 34 | B35: BENIN | C35: Airtel Router | D35: HARDWARE | F35: 1 | H35: old
A36: 35 | B36: BENIN | C36: Spectranet router | D36: HARDWARE | F36: 1 | H36: old

Sheet Dashboard
B2: Basechan International - Company Equipment & Tools Overview
B5: COMPUTERS & DEVICES | D5: OFFICE EQUIPMENT | F5: TOTAL COMPANY ITEMS | J5: ONLINE ACCOUNTS | L5: DAILY SPREADSHEETS | N5: ACTIVE TEAM MEMBERS
B6: =Calc_Data!B1 -> 22 | D6: =Calc_Data!B5 -> 116 | F6: =B6+D6 -> 138 | J6: =Calc_Data!B2 -> 52 | L6: =Calc_Data!AE6 -> 20 | N6: =Calc_Data!B3 -> 9
B7: Laptops, screens & phones | D7: Furniture & office gear | F7: All physical equipment | J7: Software & app logins | L7: Forms, records & files | N7: Staff across both offices
B35: DEVICES & EQUIPMENT BY TEAM | J35: OFFICE FURNITURE & EQUIPMENT BREAKDOWN
B36: Team / Department | C36: Devices | D36: Working Order | E36: Staff Names | F36: Office Location | G36: % of Devices | H36: % of All Items | J36: Item Category | K36: Total Count | L36: Abuja Office | M36: Benin Office | N36: Working Status | O36: % of Office Items | P36: % of All Items
B37: =HYPERLINK("#gid=2143034089&fvid=664388205", "Marketing and Sales") -> Marketing and Sales | C37: 6 | D37: 6 | E37: Cletus Anioke | F37: Abuja Office | G37: =C37/$C$43 -> 0.3 | H37: =C37/$C$45 -> 0.044117647 | J37: =HYPERLINK("#gid=258663244&fvid=1838503704", "Furniture & Desks") -> Furniture & Desks | K37: =L37+M37 -> 63 | L37: =SUMIFS('Office&Facilities'!$F$2:$F$50, 'Office&Facilities'!$B$2:$B$50, "ABUJA", 'Office&Facilities'!$D$2:$D$50, "FURNITURE") -> 55 | M37: =SUMIFS('Office&Facilities'!$F$2:$F$50, 'Office&Facilities'!$B$2:$B$50, "BENIN", 'Office&Facilities'!$D$2:$D$50, "FURNITURE") -> 8 | N37: Working / In Use | O37: =K37/$K$39 -> 0.54310345 | P37: =K37/$C$45 -> 0.46323529
B38: =HYPERLINK("#gid=2143034089&fvid=359634", "Applications & Counseling") -> Applications & Counseling | C38: 9 | D38: 8 | E38: Izunyon Blessing, Jumai, Effiong | F38: Abuja / Benin | G38: =C38/$C$43 -> 0.45 | H38: =C38/$C$45 -> 0.066176471 | J38: =HYPERLINK("#gid=258663244&fvid=1631427491", "Office Electronics & Equipment") -> Office Electronics & Equipment | K38: =L38+M38 -> 53 | L38: =SUMIFS('Office&Facilities'!$F$2:$F$50, 'Office&Facilities'!$B$2:$B$50, "ABUJA", 'Office&Facilities'!$D$2:$D$50, "HARDWARE") -> 49 | M38: =SUMIFS('Office&Facilities'!$F$2:$F$50, 'Office&Facilities'!$B$2:$B$50, "BENIN", 'Office&Facilities'!$D$2:$D$50, "HARDWARE") -> 4 | N38: Working / In Use | O38: =K38/$K$39 -> 0.45689655 | P38: =K38/$C$45 -> 0.38970588
B39: =HYPERLINK("#gid=2143034089&fvid=2088306131", "Conversion") -> Conversion | C39: 2 | D39: 2 | E39: Peter Abah, Feridu Yakubu | F39: Abuja / Benin | G39: =C39/$C$43 -> 0.1 | H39: =C39/$C$45 -> 0.014705882 | J39: Total Office Items | K39: =SUM(K37:K38) -> 116 | L39: =SUM(L37:L38) -> 104 | M39: =SUM(M37:M38) -> 12 | N39: All Items in Use | O39: =K39/$K$39 -> 1 | P39: =K39/$C$45 -> 0.85294118
B40: =HYPERLINK("#gid=2143034089&fvid=735522987", "Marketing / Applications (Joint)") -> Marketing / Applications (Joint) | C40: 1 | D40: 1 | E40: Nwaiwu Blessing (Oge) | F40: Benin City | G40: =C40/$C$43 -> 0.05 | H40: =C40/$C$45 -> 0.0073529412 | J40: Office Split by Location | K40: =K39 -> 116 | L40: =L39 -> 104 | M40: =M39 -> 12 | N40: 89.7% Abuja / 10.3% Benin | O40: 1 | P40: =K40/$C$45 -> 0.85294118
B41: =HYPERLINK("#gid=2143034089&fvid=651994796", "IT & Infrastructure Systems") -> IT & Infrastructure Systems | C41: 1 | D41: 1 | E41: Egbase Johnmary | F41: Abuja Office | G41: =C41/$C$43 -> 0.05 | H41: =C41/$C$45 -> 0.0073529412 | J41: Condition & Repairs | K41: =K39 -> 116 | L41: =L39 -> 104 | M41: =M39 -> 12 | N41: Good Condition / Working | O41: - | P41: Checked
B42: =HYPERLINK("#gid=2143034089&fvid=1716115278", "Management") -> Management | C42: 1 | D42: 1 | E42: Imuekemhe Collins | F42: Abuja Office | G42: =C42/$C$43 -> 0.05 | H42: =C42/$C$45 -> 0.0073529412 | J42: Inventory Check Status | K42: =K39 -> 116 | L42: =L39 -> 104 | M42: =M39 -> 12 | N42: 100% Checked | O42: - | P42: Current
B43: Total Team Devices | C43: =SUM(C37:C42) -> 20 | D43: =SUM(D37:D42) -> 19 | E43: 9 Active Team Members | F43: Abuja / Benin | G43: =C43/$C$43 -> 1 | H43: =C43/$C$45 -> 0.14705882 | J43: Office Locations Covered | K43: 2 | L43: 1 | M43: 1 | N43: 2 Active Offices | O43: - | P43: All Offices
B44: Office Furniture & Shared Gear | C44: =Calc_Data!B5 -> 116 | D44: =Calc_Data!B5 -> 116 | E44: Shared Office Items | F44: Abuja & Benin Branches | G44: - | H44: =C44/$C$45 -> 0.85294118 | J44: Total Office Inventory | K44: =K39 -> 116 | L44: =L39 -> 104 | M44: =M39 -> 12 | N44: In Use Across Offices | O44: 1 | P44: =K44/$C$45 -> 0.85294118
B45: Total Company Equipment | C45: =C43+C44 -> 136 | D45: =D43+D44 -> 135 | E45: 9 Team Members & Shared Items | F45: All Operating Locations | G45: - | H45: =C45/$C$45 -> 1
B46: DAILY WORKBOOKS & SPREADSHEETS | J46: STAFF & EQUIPMENT BY OFFICE
B47: Work Category | C47: Spreadsheets | D47: Main Purpose | E47: Example Files | F47: Lead Person | G47: % of Files | H47: Access Level | J47: Office Location | K47: Office Furniture | L47: Computers & Devices | M47: Total Items | N47: Main Activities | O47: % of All Items | P47: Office Status
B48: Sales & Leads Tracking | C48: =Calc_Data!AE2 -> 8 | D48: Customer inquiries & lead tracking | E48: Team Leads, Agent Leads, Status Report | F48: Marketing Team | G48: =C48/$C$53 -> 0.4 | H48: Active in Cloud | J48: =HYPERLINK("#gid=258663244&fvid=1575364930", "Abuja Head Office") -> Abuja Head Office | K48: =Calc_Data!AK2 -> 104 | L48: =Calc_Data!AJ2 -> 17 | M48: =K48+L48 -> 121 | N48: Management, Sales & Tech | O48: =M48/$M$50 -> 0.88970588 | P48: Main Office (Active)
B49: Student Applications | C49: =Calc_Data!AE3 -> 7 | D49: Student signups & school partners | E49: Admissions Responses, Crizac, Reports | F49: Admissions Team | G49: =C49/$C$53 -> 0.35 | H49: Active in Cloud | J49: =HYPERLINK("#gid=258663244&fvid=1878225735", "Benin City Branch") -> Benin City Branch | K49: =Calc_Data!AK3 -> 12 | L49: =Calc_Data!AJ3 -> 3 | M49: =K49+L49 -> 15 | N49: Student Counseling & Applications | O49: =M49/$M$50 -> 0.11029412 | P49: Branch Office (Active)
B50: General Operations | C50: =Calc_Data!AE4 -> 3 | D50: Company-wide coordination | E50: 2026 Mid Year, Referral, Branch Spreadsheets | F50: Main Office Team | G50: =C50/$C$53 -> 0.15 | H50: Internal Staff Only | J50: Total Company Footprint | K50: =SUM(K48:K49) -> 116 | L50: =SUM(L48:L49) -> 20 | M50: =SUM(M48:M49) -> 136 | N50: All Active Offices | O50: =M50/$M$50 -> 1 | P50: Company Total
B51: Finance & Payments | C51: =Calc_Data!AE5 -> 2 | D51: Bank deposits & payment tracking | E51: ALL DEPOSITS, Deposit Spreadsheet | F51: Peter Abah | G51: =C51/$C$53 -> 0.1 | H51: Finance Team Only | J51: Computer Distribution | K51: =Calc_Data!AJ5 -> 22 | L51: =Calc_Data!AJ2 -> 17 | M51: =Calc_Data!AJ3 -> 3 | N51: 85.0% Abuja / 15.0% Benin | O51: 1 | P51: Total Devices
B52: Saved Account Logins | C52: 4 | D52: Staff login details & passwords | E52: Jumai Staff Application & CRM Credentials | F52: IT & Staff | G52: - | H52: Secured | J52: Furniture & Office Gear Distribution | K52: =Calc_Data!AK5 -> 116 | L52: =Calc_Data!AK2 -> 104 | M52: =Calc_Data!AK3 -> 12 | N52: 89.7% Abuja / 10.3% Benin | O52: 1 | P52: Total Office Items
B53: Total Work Spreadsheets | C53: =SUM(C48:C51) -> 20 | D53: All active work files | E53: Tracked Spreadsheets & Forms | F53: Basechan Team | G53: =C53/$C$53 -> 1 | H53: Fully Verified | J53: Staff by Office | K53: =Calc_Data!AI5 -> 9 | L53: =Calc_Data!AI2 -> 6 | M53: =Calc_Data!AI3 -> 3 | N53: 66.7% Abuja / 33.3% Benin | O53: 1 | P53: Total Staff
B54: Cloud Storage & Backup | C54: 20 | D54: Saved in Google Drive | E54: Last Checked: Sept 2026 | F54: Tech Team | G54: 1 | H54: Up to Date | J54: All Offices Summary | K54: =Calc_Data!AL5 -> 138 | L54: =Calc_Data!AL2 -> 121 | M54: =Calc_Data!AL3 -> 15 | N54: Both Offices Connected | O54: 1 | P54: All Verified
B56: BRANCH SYSTEM USAGE & MOBILITY (FIXED VS MOBILE) | J56: UPDATED COMPUTER FLEET & WORKSTATION SETUP
B57: Branch / Office | C57: Staff Count | D57: Fixed Desktop Users | E57: Mobile Laptop Users | F57: Dual-System Users | G57: % Mobile Staff | H57: Mobility Profile | J57: Hardware / Setup Category | K57: Total Fleet | L57: Active in Use | M57: In Reserve | N57: Deployment Locations | O57: Fleet Utilization | P57: Operational Status & Notes
B58: Abuja Head Office | C58: =Calc_Data!AI8 -> 6 | D58: =Calc_Data!AJ8 -> 5 | E58: =Calc_Data!AK8 -> 2 | F58: =Calc_Data!AL8 -> 1 | G58: =Calc_Data!AM8 -> 0.33333333 | H58: Predominantly Fixed Workstations (83.3% Fixed) | J58: Mobile Laptops (HP & Acer) | K58: =Calc_Data!C18 -> 7 | L58: =Calc_Data!D18 -> 5 | M58: =Calc_Data!E18 -> 2 | N58: Abuja (2) / Benin (3) | O58: =Calc_Data!F18 -> 0.71428571 | P58: 5 Active Staff + 2 Reserve Laptops in Stock
B59: Benin City Branch | C59: =Calc_Data!AI9 -> 3 | D59: =Calc_Data!AJ9 -> 0 | E59: =Calc_Data!AK9 -> 3 | F59: =Calc_Data!AL9 -> 0 | G59: =Calc_Data!AM9 -> 1 | H59: 100% Mobile Fleet (Laptops Only) | J59: Fixed Desktop Workstations | K59: =Calc_Data!C19 -> 5 | L59: =Calc_Data!D19 -> 5 | M59: =Calc_Data!E19 -> 0 | N59: Abuja Head Office (5) | O59: =Calc_Data!F19 -> 1 | P59: Peter, Cletus, Jumai, Effiong, Collins
B60: Total Enterprise Staff | C60: =Calc_Data!AI10 -> 9 | D60: =Calc_Data!AJ10 -> 5 | E60: =Calc_Data!AK10 -> 5 | F60: =Calc_Data!AL10 -> 1 | G60: =Calc_Data!AM10 -> 0.55555556 | H60: Hybrid Operating Model | J60: Dedicated Displays & Monitors | K60: =Calc_Data!C20 -> 9 | L60: =Calc_Data!D20 -> 5 | M60: =Calc_Data!E20 -> 4 | N60: Abuja Head Office (5) / Reserve (4) | O60: =Calc_Data!F20 -> 0.55555556 | P60: 5 Active Users + 4 Reserve Monitors in Stock
B61: Dual-System Setup (Effiong O.) | C61: 1 | D61: 1 | E61: 1 | F61: 1 | G61: 1 | H61: Uses HP Desktop + HP Laptop (Applications) | J61: Dedicated Keyboards | K61: =Calc_Data!C21 -> 9 | L61: =Calc_Data!D21 -> 5 | M61: =Calc_Data!E21 -> 4 | N61: Abuja Head Office (5) / Reserve (4) | O61: =Calc_Data!F21 -> 0.55555556 | P61: 5 Active Users + 4 Reserve Keyboards in Stock
B62: Exclusively Fixed Staff | C62: =Calc_Data!AI11 -> 4 | D62: =Calc_Data!AJ11 -> 4 | E62: 0 | F62: 0 | G62: 0 | H62: Peter, Cletus, Jumai, Imuekemhe (Abuja) | J62: Dedicated Computer Mice | K62: =Calc_Data!C22 -> 8 | L62: =Calc_Data!D22 -> 5 | M62: =Calc_Data!E22 -> 3 | N62: Abuja Head Office (5) / Reserve (3) | O62: =Calc_Data!F22 -> 0.625 | P62: 5 Active Users + 3 Reserve Mice in Stock
B63: Exclusively Mobile Staff | C63: =Calc_Data!AI12 -> 4 | D63: 0 | E63: =Calc_Data!AK12 -> 4 | F63: 0 | G63: 1 | H63: Johnmary (Abuja), Izunyon, Oge, Feridu (Benin) | J63: Total Workstation & Peripheral Fleet | K63: =Calc_Data!C23 -> 38 | L63: =Calc_Data!D23 -> 25 | M63: =Calc_Data!E23 -> 13 | N63: Abuja & Benin Branches | O63: =Calc_Data!F23 -> 0.65789474 | P63: 25 Assets In Use, 13 Reserve Inventory
B64: Enterprise Mobility Ratio | C64: =Calc_Data!AM10 -> 0.55555556 | D64: 5 Desktop Users | E64: 5 Laptop Users | F64: 1 Dual User | G64: =Calc_Data!AM10 -> 0.55555556 | H64: 55.6% Staff Mobility Rate | J64: Dual Station: Effiong Oyonumo | K64: 2 | L64: 2 | M64: 0 | N64: Abuja Branch (Applications) | O64: 1 | P64: Dual Setup: HP Desktop + HP Laptop Assigned
B65: Workstation Peripheral Standard | C65: 9 | D65: 9 Keyboards | E65: 9 Mice | F65: 100% Provisioned | G65: 1 | H65: All 9 Staff Equipped with Keyboard & Mouse | J65: Active Computer Deployment Rate | K65: =K58+K59 -> 12 | L65: =L58+L59 -> 10 | M65: =M58+M59 -> 2 | N65: Abuja (7) / Benin (3) / Reserve (2) | O65: =L65/K65 -> 0.83333333 | P65: 10 Assigned Computers (5 Desktops + 5 Laptops)

Sheet Calc_Data
A1: Total Physical Assets | B1: =COUNTA(' Physical Assets'!C2:C1000) -> 22 | D1: =IFERROR(__xludf.DUMMYFUNCTION("QUERY(ARRAYFORMULA(PROPER(TRIM(' Physical Assets'!J1:J50))), ""SELECT Col1, COUNT(Col1) WHERE Col1 IS NOT NULL AND Col1 != '' AND Col1 != 'Condition' GROUP BY Col1 ORDER BY COUNT(Col1) DESC LABEL Col1 'Condition', COUNT(Col1) 'Count'"", 1)"),"Condition") -> Condition | E1: =IFERROR(__xludf.DUMMYFUNCTION("""COMPUTED_VALUE"""),"Count") -> Count | G1: =IFERROR(__xludf.DUMMYFUNCTION("QUERY(ARRAYFORMULA(PROPER(TRIM(' Physical Assets'!K1:K50))), ""SELECT Col1, COUNT(Col1) WHERE Col1 IS NOT NULL AND Col1 != '' AND Col1 != 'Status (Active/Repair/Retired)' GROUP BY Col1 ORDER BY COUNT(Col1) DESC LABEL Col1 'Status', COUNT(Col1) 'Count'"", "&"1)"),"Status") -> Status | H1: =IFERROR(__xludf.DUMMYFUNCTION("""COMPUTED_VALUE"""),"Count") -> Count | J1: Physical Condition | K1: Count | M1: =IFERROR(__xludf.DUMMYFUNCTION("IF(COUNTA('Data&Workbooks'!F2:F1000)=0, {""Department"", ""Count""; ""No Data"", 0}, QUERY('Data&Workbooks'!A1:H1000, ""SELECT F, COUNT(F) WHERE F IS NOT NULL AND F != 'Department' GROUP BY F LABEL F 'Department', COUNT(F) 'Count'"", 1))"),"Department") -> Department | N1: =IFERROR(__xludf.DUMMYFUNCTION("""COMPUTED_VALUE"""),"Count") -> Count | P1: =IFERROR(__xludf.DUMMYFUNCTION("QUERY(MAP(' Physical Assets'!G2:G23, LAMBDA(d, IFS(ISBLANK(d), ""Reserve Devices"", LOWER(TRIM(d))="""", ""Reserve Devices"", LOWER(TRIM(d))=""marketing/applications"", ""Marketing / Applications (Joint)"", LOWER(TRIM(d))=""it & infrastructure systems"", "&"""IT & Infrastructure Systems"", REGEXMATCH(LOWER(TRIM(d)), ""^app""), ""Applications & Counseling"", REGEXMATCH(LOWER(TRIM(d)), ""^market""), ""Marketing and Sales"", REGEXMATCH(LOWER(TRIM(d)), ""^conver""), ""Conversion"", REGEXMATCH(LOWER(TRIM(d)), ""^"&"manage""), ""Management"", TRUE, TRIM(d)))), ""SELECT Col1, COUNT(Col1) WHERE Col1 IS NOT NULL AND Col1 != '' GROUP BY Col1 ORDER BY COUNT(Col1) DESC LABEL Col1 'Department', COUNT(Col1) 'Total Assets'"")"),"Department") -> Department | Q1: =IFERROR(__xludf.DUMMYFUNCTION("""COMPUTED_VALUE"""),"Total Assets") -> Total Assets | S1: =IFERROR(__xludf.DUMMYFUNCTION("QUERY('Office&Facilities'!D1:F100, ""SELECT D, SUM(F) WHERE D IS NOT NULL AND D != 'Category (Furniture/Network/Peripheral)' GROUP BY D ORDER BY SUM(F) DESC LABEL D 'Category', SUM(F) 'Total Assets'"", 1)"),"Category") -> Category | T1: =IFERROR(__xludf.DUMMYFUNCTION("""COMPUTED_VALUE"""),"Total Assets") -> Total Assets | V1: Location | W1: Total Assets | Y1: Asset Type | Z1: Total Assets | AA1: =IFERROR(__xludf.DUMMYFUNCTION("QUERY(MAP(FILTER(' Digital&Accounts'!B2:B57, ' Digital&Accounts'!B2:B57<>""""), LAMBDA(p, IFS(REGEXMATCH(LOWER(p), ""crizac""), ""Crizac Portal"", REGEXMATCH(LOWER(p), ""si[- /]?uk|si-app""), ""SI-UK Portal"", REGEXMATCH(LOWER(p), ""basechan""), ""Basecha"&"n CRM / App"", REGEXMATCH(LOWER(p), ""google|gmail|spreadsheet""), ""Google Workspace"", REGEXMATCH(LOWER(p), ""firm""), ""Firmli CRM"", REGEXMATCH(LOWER(p), ""edvoy""), ""Edvoy Portal"", REGEXMATCH(LOWER(p), ""microsoft""), ""Microsoft 365"", REGEXMATCH("&"LOWER(p), ""canva""), ""Canva Pro"", REGEXMATCH(LOWER(p), ""ceg|sunderland|uap|lsbu""), ""University Portals"", TRUE, ""Other Platforms""))), ""SELECT Col1, COUNT(Col1) WHERE Col1 IS NOT NULL GROUP BY Col1 ORDER BY COUNT(Col1) DESC LABEL Col1 'Platform / "&"Software', COUNT(Col1) 'Account Count'"")"),"Platform / Software") -> Platform / Software | AB1: =IFERROR(__xludf.DUMMYFUNCTION("""COMPUTED_VALUE"""),"Account Count") -> Account Count | AD1: Operational Domain | AE1: Active Workbooks | AH1: Branch | AI1: Staff Headcount | AJ1: Hardware Assets | AK1: Facility Assets | AL1: Total Combined
A2: Total Digital Accounts | B2: =COUNTA(' Digital&Accounts'!B2:B57) -> 52 | D2: =IFERROR(__xludf.DUMMYFUNCTION("""COMPUTED_VALUE"""),"Fairly Used In Good Condition") -> Fairly Used In Good Condition | E2: =IFERROR(__xludf.DUMMYFUNCTION("""COMPUTED_VALUE"""),5.0) -> 5 | G2: =IFERROR(__xludf.DUMMYFUNCTION("""COMPUTED_VALUE"""),"Active") -> Active | H2: =IFERROR(__xludf.DUMMYFUNCTION("""COMPUTED_VALUE"""),14.0) -> 14 | J2: new and in good condition | K2: =COUNTIF(' Physical Assets'!J:J, J2) -> 1 | M2: =IFERROR(__xludf.DUMMYFUNCTION("""COMPUTED_VALUE"""),"ALL") -> ALL | N2: =IFERROR(__xludf.DUMMYFUNCTION("""COMPUTED_VALUE"""),3.0) -> 3 | P2: =IFERROR(__xludf.DUMMYFUNCTION("""COMPUTED_VALUE"""),"Applications & Counseling") -> Applications & Counseling | Q2: =IFERROR(__xludf.DUMMYFUNCTION("""COMPUTED_VALUE"""),9.0) -> 9 | S2: =IFERROR(__xludf.DUMMYFUNCTION("""COMPUTED_VALUE"""),"FURNITURE") -> FURNITURE | T2: =IFERROR(__xludf.DUMMYFUNCTION("""COMPUTED_VALUE"""),63.0) -> 63 | V2: Abuja Branch | W2: =COUNTIF(' Physical Assets'!$H$2:$H$50, "Abuja Branch") + SUMIF('Office&Facilities'!$B$2:$B$50, "ABUJA", 'Office&Facilities'!$F$2:$F$50) -> 121 | Y2: Laptops & Devices | Z2: =B1 -> 22 | AA2: =IFERROR(__xludf.DUMMYFUNCTION("""COMPUTED_VALUE"""),"University Portals") -> University Portals | AB2: =IFERROR(__xludf.DUMMYFUNCTION("""COMPUTED_VALUE"""),10.0) -> 10 | AD2: Marketing & Lead Tracking | AE2: =COUNTIF('Data&Workbooks'!F2:F24, "*Lead*") + COUNTIF('Data&Workbooks'!B2:B24, "*Marketing*") + COUNTIF('Data&Workbooks'!B2:B24, "*Leads*") + COUNTIF('Data&Workbooks'!B2:B24, "*Agent*") -> 8 | AH2: Abuja Branch | AI2: =COUNTIF('Staff Inventory'!$I$2:$I$50, "Abuja Branch") -> 6 | AJ2: =COUNTIF(' Physical Assets'!$H$2:$H$50, "Abuja Branch") -> 17 | AK2: =SUMIF('Office&Facilities'!$B$2:$B$50, "ABUJA", 'Office&Facilities'!$F$2:$F$50) -> 104 | AL2: =AJ2+AK2 -> 121
A3: Active Staff | B3: =COUNTA('Staff Inventory'!B2:B1000) -> 9 | D3: =IFERROR(__xludf.DUMMYFUNCTION("""COMPUTED_VALUE"""),"In Good Condition") -> In Good Condition | E3: =IFERROR(__xludf.DUMMYFUNCTION("""COMPUTED_VALUE"""),5.0) -> 5 | G3: =IFERROR(__xludf.DUMMYFUNCTION("""COMPUTED_VALUE"""),"Functional") -> Functional | H3: =IFERROR(__xludf.DUMMYFUNCTION("""COMPUTED_VALUE"""),6.0) -> 6 | J3: fairly used in good condition | K3: =COUNTIF(' Physical Assets'!J:J, J3) -> 5 | M3: =IFERROR(__xludf.DUMMYFUNCTION("""COMPUTED_VALUE"""),"Application") -> Application | N3: =IFERROR(__xludf.DUMMYFUNCTION("""COMPUTED_VALUE"""),3.0) -> 3 | P3: =IFERROR(__xludf.DUMMYFUNCTION("""COMPUTED_VALUE"""),"Marketing and Sales") -> Marketing and Sales | Q3: =IFERROR(__xludf.DUMMYFUNCTION("""COMPUTED_VALUE"""),6.0) -> 6 | S3: =IFERROR(__xludf.DUMMYFUNCTION("""COMPUTED_VALUE"""),"HARDWARE") -> HARDWARE | T3: =IFERROR(__xludf.DUMMYFUNCTION("""COMPUTED_VALUE"""),53.0) -> 53 | V3: Benin Branch | W3: =COUNTIF(' Physical Assets'!$H$2:$H$50, "Benin Branch") + SUMIF('Office&Facilities'!$B$2:$B$50, "BENIN", 'Office&Facilities'!$F$2:$F$50) -> 15 | Y3: Office Furniture & Gear | Z3: =B5 -> 116 | AA3: =IFERROR(__xludf.DUMMYFUNCTION("""COMPUTED_VALUE"""),"Crizac Portal") -> Crizac Portal | AB3: =IFERROR(__xludf.DUMMYFUNCTION("""COMPUTED_VALUE"""),8.0) -> 8 | AD3: Admissions & Applications | AE3: =COUNTIF('Data&Workbooks'!F2:F24, "*App*") + 2 -> 7 | AH3: Benin Branch | AI3: =COUNTIF('Staff Inventory'!$I$2:$I$50, "Benin Branch") -> 3 | AJ3: =COUNTIF(' Physical Assets'!$H$2:$H$50, "Benin Branch") -> 3 | AK3: =SUMIF('Office&Facilities'!$B$2:$B$50, "BENIN", 'Office&Facilities'!$F$2:$F$50) -> 12 | AL3: =AJ3+AK3 -> 15
A4: Assets in Repair | B4: =COUNTIF(' Physical Assets'!K2:K1000, "*Repair*") -> 0 | D4: =IFERROR(__xludf.DUMMYFUNCTION("""COMPUTED_VALUE"""),"Good") -> Good | E4: =IFERROR(__xludf.DUMMYFUNCTION("""COMPUTED_VALUE"""),4.0) -> 4 | G4: =IFERROR(__xludf.DUMMYFUNCTION("""COMPUTED_VALUE"""),"Retired") -> Retired | H4: =IFERROR(__xludf.DUMMYFUNCTION("""COMPUTED_VALUE"""),1.0) -> 1 | J4: fairly used and in bad condition | K4: =COUNTIF(' Physical Assets'!J:J, J4) -> 1 | M4: =IFERROR(__xludf.DUMMYFUNCTION("""COMPUTED_VALUE"""),"Application/Report") -> Application/Report | N4: =IFERROR(__xludf.DUMMYFUNCTION("""COMPUTED_VALUE"""),2.0) -> 2 | P4: =IFERROR(__xludf.DUMMYFUNCTION("""COMPUTED_VALUE"""),"Conversion") -> Conversion | Q4: =IFERROR(__xludf.DUMMYFUNCTION("""COMPUTED_VALUE"""),2.0) -> 2 | V4: Reserve Devices | W4: =COUNTIF(' Physical Assets'!$H$2:$H$23, "") -> 2 | Y4: Total Enterprise Assets | Z4: =SUM(Z2:Z3) -> 138 | AA4: =IFERROR(__xludf.DUMMYFUNCTION("""COMPUTED_VALUE"""),"SI-UK Portal") -> SI-UK Portal | AB4: =IFERROR(__xludf.DUMMYFUNCTION("""COMPUTED_VALUE"""),8.0) -> 8 | AD4: Operations & Multi-Branch | AE4: =COUNTIF('Data&Workbooks'!F2:F24, "ALL") -> 3 | AH4: Reserve / Unassigned | AI4: 0 | AJ4: =COUNTIF(' Physical Assets'!$H$2:$H$23, "") -> 2 | AK4: 0 | AL4: =AJ4+AK4 -> 2
A5: Office & Facilities Assets | B5: =SUM('Office&Facilities'!F2:F1000) -> 116 | D5: =IFERROR(__xludf.DUMMYFUNCTION("""COMPUTED_VALUE"""),"Used") -> Used | E5: =IFERROR(__xludf.DUMMYFUNCTION("""COMPUTED_VALUE"""),3.0) -> 3 | J5: faulty | K5: =COUNTIF(' Physical Assets'!J:J, J5) -> 0 | M5: =IFERROR(__xludf.DUMMYFUNCTION("""COMPUTED_VALUE"""),"Conversion") -> Conversion | N5: =IFERROR(__xludf.DUMMYFUNCTION("""COMPUTED_VALUE"""),2.0) -> 2 | P5: =IFERROR(__xludf.DUMMYFUNCTION("""COMPUTED_VALUE"""),"Reserve Devices") -> Reserve Devices | Q5: =IFERROR(__xludf.DUMMYFUNCTION("""COMPUTED_VALUE"""),2.0) -> 2 | V5: Total Enterprise | W5: =SUM(W2:W4) -> 138 | AA5: =IFERROR(__xludf.DUMMYFUNCTION("""COMPUTED_VALUE"""),"Google Workspace") -> Google Workspace | AB5: =IFERROR(__xludf.DUMMYFUNCTION("""COMPUTED_VALUE"""),7.0) -> 7 | AD5: Conversion & Financials | AE5: =COUNTIF('Data&Workbooks'!F2:F24, "Conversion") -> 2 | AH5: Total Enterprise | AI5: =SUM(AI2:AI4) -> 9 | AJ5: =SUM(AJ2:AJ4) -> 22 | AK5: =SUM(AK2:AK4) -> 116 | AL5: =SUM(AL2:AL4) -> 138
D6: =IFERROR(__xludf.DUMMYFUNCTION("""COMPUTED_VALUE"""),"Fairly Used And In Bad Condition") -> Fairly Used And In Bad Condition | E6: =IFERROR(__xludf.DUMMYFUNCTION("""COMPUTED_VALUE"""),1.0) -> 1 | J6: damaged | K6: =COUNTIF(' Physical Assets'!J:J, J6) -> 0 | M6: =IFERROR(__xludf.DUMMYFUNCTION("""COMPUTED_VALUE"""),"Counselor") -> Counselor | N6: =IFERROR(__xludf.DUMMYFUNCTION("""COMPUTED_VALUE"""),1.0) -> 1 | P6: =IFERROR(__xludf.DUMMYFUNCTION("""COMPUTED_VALUE"""),"IT & Infrastructure Systems") -> IT & Infrastructure Systems | Q6: =IFERROR(__xludf.DUMMYFUNCTION("""COMPUTED_VALUE"""),1.0) -> 1 | AA6: =IFERROR(__xludf.DUMMYFUNCTION("""COMPUTED_VALUE"""),"Basechan CRM / App") -> Basechan CRM / App | AB6: =IFERROR(__xludf.DUMMYFUNCTION("""COMPUTED_VALUE"""),6.0) -> 6 | AD6: Total Document Assets | AE6: =SUM(AE2:AE5) -> 20
D7: =IFERROR(__xludf.DUMMYFUNCTION("""COMPUTED_VALUE"""),"Fairly Used And In Good Condition") -> Fairly Used And In Good Condition | E7: =IFERROR(__xludf.DUMMYFUNCTION("""COMPUTED_VALUE"""),1.0) -> 1 | J7: old | K7: =COUNTIF(' Physical Assets'!J:J, J7) -> 0 | M7: =IFERROR(__xludf.DUMMYFUNCTION("""COMPUTED_VALUE"""),"Lead management/Marketing") -> Lead management/Marketing | N7: =IFERROR(__xludf.DUMMYFUNCTION("""COMPUTED_VALUE"""),3.0) -> 3 | P7: =IFERROR(__xludf.DUMMYFUNCTION("""COMPUTED_VALUE"""),"Management") -> Management | Q7: =IFERROR(__xludf.DUMMYFUNCTION("""COMPUTED_VALUE"""),1.0) -> 1 | AA7: =IFERROR(__xludf.DUMMYFUNCTION("""COMPUTED_VALUE"""),"Edvoy Portal") -> Edvoy Portal | AB7: =IFERROR(__xludf.DUMMYFUNCTION("""COMPUTED_VALUE"""),4.0) -> 4 | AH7: Branch | AI7: Staff Headcount | AJ7: Fixed Desktop Users | AK7: Mobile Laptop Users | AL7: Dual-System Users | AM7: Mobility Ratio
D8: =IFERROR(__xludf.DUMMYFUNCTION("""COMPUTED_VALUE"""),"Lags, Freezes, And Malfunctions Frequently") -> Lags, Freezes, And Malfunctions Frequently | E8: =IFERROR(__xludf.DUMMYFUNCTION("""COMPUTED_VALUE"""),1.0) -> 1 | J8: need replacement | K8: =COUNTIF(' Physical Assets'!J:J, J8) -> 0 | M8: =IFERROR(__xludf.DUMMYFUNCTION("""COMPUTED_VALUE"""),"Managemet") -> Managemet | N8: =IFERROR(__xludf.DUMMYFUNCTION("""COMPUTED_VALUE"""),2.0) -> 2 | P8: =IFERROR(__xludf.DUMMYFUNCTION("""COMPUTED_VALUE"""),"Marketing / Applications (Joint)") -> Marketing / Applications (Joint) | Q8: =IFERROR(__xludf.DUMMYFUNCTION("""COMPUTED_VALUE"""),1.0) -> 1 | AA8: =IFERROR(__xludf.DUMMYFUNCTION("""COMPUTED_VALUE"""),"Canva Pro") -> Canva Pro | AB8: =IFERROR(__xludf.DUMMYFUNCTION("""COMPUTED_VALUE"""),3.0) -> 3 | AH8: Abuja Branch | AI8: =COUNTIF('Staff Inventory'!I2:I10, "Abuja Branch") -> 6 | AJ8: 5 | AK8: 2 | AL8: 1 | AM8: =AK8/AI8 -> 0.33333333
D9: =IFERROR(__xludf.DUMMYFUNCTION("""COMPUTED_VALUE"""),"New And In Good Condition") -> New And In Good Condition | E9: =IFERROR(__xludf.DUMMYFUNCTION("""COMPUTED_VALUE"""),1.0) -> 1 | M9: =IFERROR(__xludf.DUMMYFUNCTION("""COMPUTED_VALUE"""),"User") -> User | N9: =IFERROR(__xludf.DUMMYFUNCTION("""COMPUTED_VALUE"""),3.0) -> 3 | AA9: =IFERROR(__xludf.DUMMYFUNCTION("""COMPUTED_VALUE"""),"Firmli CRM") -> Firmli CRM | AB9: =IFERROR(__xludf.DUMMYFUNCTION("""COMPUTED_VALUE"""),3.0) -> 3 | AH9: Benin Branch | AI9: =COUNTIF('Staff Inventory'!I2:I10, "Benin Branch") -> 3 | AJ9: 0 | AK9: 3 | AL9: 0 | AM9: =AK9/AI9 -> 1
AA10: =IFERROR(__xludf.DUMMYFUNCTION("""COMPUTED_VALUE"""),"Microsoft 365") -> Microsoft 365 | AB10: =IFERROR(__xludf.DUMMYFUNCTION("""COMPUTED_VALUE"""),2.0) -> 2 | AH10: Total Enterprise | AI10: =SUM(AI8:AI9) -> 9 | AJ10: =SUM(AJ8:AJ9) -> 5 | AK10: =SUM(AK8:AK9) -> 5 | AL10: =SUM(AL8:AL9) -> 1 | AM10: =AK10/AI10 -> 0.55555556
AA11: =IFERROR(__xludf.DUMMYFUNCTION("""COMPUTED_VALUE"""),"Other Platforms") -> Other Platforms | AB11: =IFERROR(__xludf.DUMMYFUNCTION("""COMPUTED_VALUE"""),1.0) -> 1 | AH11: Fixed-Only Users | AI11: =AJ10-AL10 -> 4 | AJ11: =AJ10-AL10 -> 4 | AK11: 0 | AL11: 0 | AM11: 0
AH12: Mobile-Only Users | AI12: =AK10-AL10 -> 4 | AJ12: 0 | AK12: =AK10-AL10 -> 4 | AL12: 0 | AM12: 1
A17: Setup / Device Category | B17: Mobility Type | C17: Total Units | D17: Active / Assigned | E17: Unused / Reserve | F17: Utilization Rate
A18: Laptops (Mobile Workstations) | B18: Mobile | C18: 7 | D18: 5 | E18: =C18-D18 -> 2 | F18: =D18/C18 -> 0.71428571
A19: Desktops (Fixed Workstations) | B19: Fixed | C19: 5 | D19: 5 | E19: =C19-D19 -> 0 | F19: =D19/C19 -> 1
A20: Dedicated Displays & Monitors | B20: Fixed Display | C20: 9 | D20: 5 | E20: =C20-D20 -> 4 | F20: =D20/C20 -> 0.55555556
A21: Dedicated Keyboards | B21: Peripherals / Accessories | C21: 9 | D21: 5 | E21: =C21-D21 -> 4 | F21: =D21/C21 -> 0.55555556
A22: Dedicated Computer Mice | B22: Peripherals / Accessories | C22: 8 | D22: 5 | E22: =C22-D22 -> 3 | F22: =D22/C22 -> 0.625
A23: Total Workstation & Peripheral Fleet | B23: All Equipment | C23: =SUM(C18:C22) -> 38 | D23: =SUM(D18:D22) -> 25 | E23: =SUM(E18:E22) -> 13 | F23: =D23/C23 -> 0.65789474
